Workbook

Sheet README
A1: Barev dzez
A4: Purpose
A5: Use this workbook to collect evidence across seven strategic industries, compare market size and forecast potential, document PESTLE and Five Forces, and prioritize which domains deserve deeper business-unit audits.
A8: Recommended workflow
A9: 1. Review or edit industry definitions in the Definitions sheet.
A10: 2. Review the Assumptions sheet: controls at the top, global trend assumptions at the bottom.
A11: 3. Record every source in Sources_Log and paste the main URL in Industry_Data.
A12: 4. Use each industry sheet for narrative notes, demand drivers, PESTLE, Five Forces, risks, and decision comments.
A13: 5. Review Ranking_Summary to see which industry scores highest based on your weights.
A14: 6. Adjust weights in Assumptions if your strategic priorities change.
A16: Color legend
A17: Format | B17: Meaning
A18: Blue text / light blue fill | B18: Manual inputs and editable assumptions
A19: Black text | B19: Formula / calculated cells
A20: Green fill | B20: Linked / reference cells
A21: Gray fill | B21: Static text or definitions
A22: Orange fill | B22: Review / caution areas
A23: Purple fill | B23: Controls / weights / logic
A24: Teal fill | B24: Summary KPI or key decision cells
A25: Yellow fill | B25: Source-URL paste / manually checked external references
A27: New market sheets added
A28: Target_Markets_Regions | B28: Regional market figures and short PESTLE explanations, based on the Word market logic.
A29: Target_Markets_Countries | B29: Country list with simple market-size and growth outlook for prioritization.
A30: Target_Markets_By_Industry | B30: Country-by-country view of demand level for all 7 industry domains.

Sheet Definitions
A1: Industry Definitions
A4: Code | B4: Industry Name | C4: Working Definition | D4: Typical Products / Systems | E4: Typical Customers | F4: Strategic Note
A5: TEL | B5: Telecommunications Infrastructure | C5: Physical and technological systems that enable the transmission of voice, data, and internet services across local, regional, and global communication networks. | D5: fiber optic cables; ODN/closures/cabinets; passive optical components; PON equipment; transmission systems | E5: telecom operators; ISPs; infrastructure contractors; system integrators | F5: Backbone connectivity domain supported by broadband rollout, 5G backhaul, and public network investment.
A6: NET | B6: Networking & Data Systems | C6: Hardware and software systems that route, distribute, secure, and manage data traffic across enterprise, campus, carrier, and cloud environments. | D6: switches; routers; wireless access points; firewalls; structured cabling; network management platforms | E6: enterprises; IT integrators; telecom operators; cloud and service providers | F6: Benefits from enterprise digitalization, cloud migration, and traffic growth, but rivalry is intense.
A7: SEC | B7: Security & Surveillance | C7: Technologies used to monitor, control, and protect physical environments, assets, and people through integrated security and surveillance systems. | D7: CCTV cameras; VMS; NVR/DVR; access control; alarms; perimeter systems | E7: security integrators; facility operators; government contractors; infrastructure developers | F7: Demand is shaped by safety budgets, regulation, and rising use of AI-enabled monitoring.
A8: SBL | B8: Smart Building & IoT Systems | C8: Connected building systems that integrate sensors, controllers, software, and devices to optimize building operations, energy use, communications, and user experience. | D8: BMS; intercom; access control; IoT sensors; automation controllers; smart office and smart home devices | E8: developers; EPCs; smart-building integrators; facility managers; real estate owners | F8: High-growth domain tied to efficiency retrofits, premium real estate, and smart-city investment.
A9: DCA | B9: Data Centre & AI Infrastructure | C9: High-performance infrastructure used to support cloud, storage, compute, and AI workloads, including dense connectivity, power, and cooling systems. | D9: high-speed optical interconnects; racks; structured connectivity; power distribution; cooling systems | E9: hyperscalers; colocation operators; cloud providers; AI infrastructure companies; governments | F9: Fastest strategic growth cluster, but constrained by power, capital intensity, and technical complexity.
A10: ROB | B10: Robotics & Intelligent Devices | C10: Automated and AI-enabled machines used to perform physical or service tasks with limited human intervention across commercial, logistics, and operational environments. | D10: service robots; delivery robots; cleaning robots; warehouse robots; robot control systems; AI sensors | E10: logistics operators; hospitals; hotels; retailers; automation integrators; industrial users | F10: High upside from labor shortages and automation, but adoption depends on ROI and integration maturity.
A11: CEV | B11: Commercial Electronics & Visual Systems | C11: Electronic and display-based systems used in commercial, professional, and public environments for visualization, communication, collaboration, and monitoring. | D11: commercial displays; video walls; digital signage; control room screens; conferencing systems | E11: AV integrators; enterprises; retail chains; public facilities; transport hubs; control centers | F11: Useful adjacent domain, though more capex-cyclical and price-driven than core infrastructure categories.

Sheet Assumptions
A1: Model Controls, Years, and Weighting
A4: Control | B4: Value | C4: Note | E4: Score | F4: Guide | G4: Use for
A5: Base Year | B5: 2025 | C5: Edit if your study uses a different current year | E5: 1 | F5: Very weak / unfavorable | G5: Qualitative scores in Industry_Data
A6: Forecast Year | B6: 2030 | C6: Edit if your horizon changes | E6: 5 | F6: Average / mixed | G6: Qualitative scores in Industry_Data
A7: Forecast Period (years) | B7: =B6-B5 | C7: Calculated | E7: 10 | F7: Very strong / favorable | G7: Qualitative scores in Industry_Data
A9: Scoring Component | B9: Weight | C9: How to read it
A10: Current market size | B10: 0.15 | C10: Larger current market increases dominance potential
A11: Forecast market size | B11: 0.2 | C11: Larger end-state market increases dominance potential
A12: CAGR | B12: 0.2 | C12: Higher growth rate increases future dominance potential
A13: Technology momentum | B13: 0.1 | C13: 1-10 score entered by user
A14: Regional opportunity | B14: 0.1 | C14: 1-10 score based on target markets
A15: Strategic fit | B15: 0.1 | C15: 1-10 score based on your business fit
A16: Competition attractiveness | B16: 0.075 | C16: Derived from competitive intensity (lower rivalry is better)
A17: Regulatory favorability | B17: 0.075 | C17: 1-10 score entered by user
A18: Weight check | B18: =SUM(B10:B17) | C18: Should equal 100.0%
A21: Bucket | B21: Minimum Score | C21: Interpretation
A22: Dominant Potential | B22: 0.75 | C22: Likely strategic priority if evidence confirms
A23: Strong Candidate | B23: 0.6 | C23: Promising and worth deeper analysis
A24: Watchlist | B24: 0.45 | C24: Monitor or study further
A25: Emerging / Niche | B25: 0 | C25: Potential but not yet dominant
A28: Global Trend Assumption | B28: Importance (1-10) | C28: Why it matters | D28: Main source URL
A29: AI data-centre buildout | B29: 10 | C29: Pushes demand for dense optics, power, cooling, and advanced networking. | D29: https://www.iea.org/reports/energy-and-ai/energy-demand-from-ai
A30: Broadband + 5G traffic growth | B30: 9 | C30: Supports fiber rollout, access upgrades, and core/edge capacity expansion. | D30: https://www.ericsson.com/en/reports-and-papers/mobility-report/dataforecasts/mobile-traffic-forecast
A31: Security and critical-infrastructure protection | B31: 8 | C31: Sustains spending on surveillance, access control, and resilient site security. | D31: https://www.marketsandmarkets.com/Market-Reports/physical-security-market-1014.html
A32: Energy-efficiency retrofit pressure | B32: 8 | C32: Accelerates smart-building controls, BMS, and building IoT upgrades. | D32: https://www.grandviewresearch.com/industry-analysis/global-smart-buildings-market
A33: Supply-chain diversification and vendor restrictions | B33: 8 | C33: Raises sourcing complexity but creates openings for OEM, platform, and regional distribution models. | D33: https://www.pwc.com/us/en/industries/tmt/library/geo-economic-shifts-in-tech-and-telecom.html
A34: Labor shortages and automation economics | B34: 7 | C34: Improves the business case for robotics and intelligent devices. | D34: https://ifr.org/ifr-press-releases/news/global-robot-demand-in-factories-doubles-over-10-years
A35: Smart retail / public-space modernization | B35: 6 | C35: Supports demand for signage, displays, and commercial AV systems. | D35: https://www.grandviewresearch.com/industry-analysis/commercial-display-market

Sheet Industry_Data
A1: Industry Data Entry and Auto-Scoring
A4: Code | B4: Industry | C4: Current Market Size ($m) | D4: Forecast Market Size ($m) | E4: CAGR | F4: Absolute Growth ($m) | G4: Technology Momentum (1-10) | H4: Regional Opportunity (1-10) | I4: Strategic Fit (1-10) | J4: Competitive Intensity (1-10) | K4: Competition Attractiveness | L4: Regulatory Favorability (1-10) | M4: Data Completeness | N4: Data Confidence (1-5) | O4: Dominance Score | P4: Rank | Q4: Bucket | R4: Key Forecast Comment | S4: Risks / Constraints | T4: Priority Actions | U4: Main Source URL
A5: TEL | B5: Telecommunications Infrastructure | C5: 36.69 | D5: 58.65 | E5: =IF(AND(C5>0,D5>0,Assumptions!$B$7>0),(D5/C5)^(1/Assumptions!$B$7)-1,"") | F5: =IF(AND(C5<>"",D5<>""),D5-C5,"") | G5: 8 | H5: 8 | I5: 9 | J5: 8 | K5: =IF(J5="","",1-(J5-1)/9) | L5: 7 | M5: =COUNT(C5,D5,G5,H5,I5,J5,L5)/7 | N5: 4 | O5: =IF(COUNT(C5,D5,G5,H5,I5,J5,L5)=0,"",(IF(MAX($C$5:$C$11)>0,C5/MAX($C$5:$C$11),0)*Assumptions!$B$10+IF(MAX($D$5:$D$11)>0,D5/MAX($D$5:$D$11),0)*Assumptions!$B$11+IF(MAX($E$5:$E$11)>0,E5/MAX($E$5:$E$11),0)*Assumptions!$B$12+IF(G5<>"",G5/10,0)*Assumptions!$B$13+IF(H5<>"",H5/10,0)*Assumptions!$B$14+IF(I5<>"",I5/10,0)*Assumptions!$B$15+IF(K5<>"",K5,0)*Assumptions!$B$16+IF(L5<>"",L5/10,0)*Assumptions!$B$17)*M5) | P5: =IF(O5="","",RANK(O5,$O$5:$O$11,0)+COUNTIF($O$5:O5,O5)-1) | Q5: =IF(O5="","",IF(O5>=Assumptions!$B$22,Assumptions!$A$22,IF(O5>=Assumptions!$B$23,Assumptions!$A$23,IF(O5>=Assumptions!$B$24,Assumptions!$A$24,Assumptions!$A$25)))) | R5: Optics growth is supported by AI interconnect demand, 5G backhaul, and FTTH expansion. | S5: Carrier capex cycles and vendor restrictions can delay programs. | T5: Prioritize passive + active fiber ecosystem, OEM sourcing, and ISP channels. | U5: https://www.marketsandmarkets.com/PressReleases/fiber-optic-component.asp
A6: NET | B6: Networking & Data Systems | C6: 124.59 | D6: 193.77 | E6: =IF(AND(C6>0,D6>0,Assumptions!$B$7>0),(D6/C6)^(1/Assumptions!$B$7)-1,"") | F6: =IF(AND(C6<>"",D6<>""),D6-C6,"") | G6: 8 | H6: 8 | I6: 8 | J6: 8 | K6: =IF(J6="","",1-(J6-1)/9) | L6: 7 | M6: =COUNT(C6,D6,G6,H6,I6,J6,L6)/7 | N6: 4 | O6: =IF(COUNT(C6,D6,G6,H6,I6,J6,L6)=0,"",(IF(MAX($C$5:$C$11)>0,C6/MAX($C$5:$C$11),0)*Assumptions!$B$10+IF(MAX($D$5:$D$11)>0,D6/MAX($D$5:$D$11),0)*Assumptions!$B$11+IF(MAX($E$5:$E$11)>0,E6/MAX($E$5:$E$11),0)*Assumptions!$B$12+IF(G6<>"",G6/10,0)*Assumptions!$B$13+IF(H6<>"",H6/10,0)*Assumptions!$B$14+IF(I6<>"",I6/10,0)*Assumptions!$B$15+IF(K6<>"",K6,0)*Assumptions!$B$16+IF(L6<>"",L6/10,0)*Assumptions!$B$17)*M6) | P6: =IF(O6="","",RANK(O6,$O$5:$O$11,0)+COUNTIF($O$5:O6,O6)-1) | Q6: =IF(O6="","",IF(O6>=Assumptions!$B$22,Assumptions!$A$22,IF(O6>=Assumptions!$B$23,Assumptions!$A$23,IF(O6>=Assumptions!$B$24,Assumptions!$A$24,Assumptions!$A$25)))) | R6: Cloud migration, wireless upgrades, and secure enterprise architectures keep demand resilient. | S6: High rivalry, fast refresh cycles, and incumbent vendor lock-in compress margins. | T6: Focus on value-added distribution, bundled security/networking, and mid-market integration. | U6: https://www.marketsandmarkets.com/PressReleases/enterprise-networking.asp
A7: SEC | B7: Security & Surveillance | C7: 120.79 | D7: 151.5 | E7: =IF(AND(C7>0,D7>0,Assumptions!$B$7>0),(D7/C7)^(1/Assumptions!$B$7)-1,"") | F7: =IF(AND(C7<>"",D7<>""),D7-C7,"") | G7: 8 | H7: 8 | I7: 8 | J7: 7 | K7: =IF(J7="","",1-(J7-1)/9) | L7: 8 | M7: =COUNT(C7,D7,G7,H7,I7,J7,L7)/7 | N7: 4 | O7: =IF(COUNT(C7,D7,G7,H7,I7,J7,L7)=0,"",(IF(MAX($C$5:$C$11)>0,C7/MAX($C$5:$C$11),0)*Assumptions!$B$10+IF(MAX($D$5:$D$11)>0,D7/MAX($D$5:$D$11),0)*Assumptions!$B$11+IF(MAX($E$5:$E$11)>0,E7/MAX($E$5:$E$11),0)*Assumptions!$B$12+IF(G7<>"",G7/10,0)*Assumptions!$B$13+IF(H7<>"",H7/10,0)*Assumptions!$B$14+IF(I7<>"",I7/10,0)*Assumptions!$B$15+IF(K7<>"",K7,0)*Assumptions!$B$16+IF(L7<>"",L7/10,0)*Assumptions!$B$17)*M7) | P7: =IF(O7="","",RANK(O7,$O$5:$O$11,0)+COUNTIF($O$5:O7,O7)-1) | Q7: =IF(O7="","",IF(O7>=Assumptions!$B$22,Assumptions!$A$22,IF(O7>=Assumptions!$B$23,Assumptions!$A$23,IF(O7>=Assumptions!$B$24,Assumptions!$A$24,Assumptions!$A$25)))) | R7: Security budgets remain stable and AI analytics expand use cases beyond basic monitoring. | S7: Privacy regulation, cybersecurity requirements, and price pressure on hardware. | T7: Build bundled camera + access + analytics offers and focus on regulated verticals. | U7: https://www.marketsandmarkets.com/Market-Reports/physical-security-market-1014.html
A8: SBL | B8: Smart Building & IoT Systems | C8: 141.79 | D8: 336.94 | E8: =IF(AND(C8>0,D8>0,Assumptions!$B$7>0),(D8/C8)^(1/Assumptions!$B$7)-1,"") | F8: =IF(AND(C8<>"",D8<>""),D8-C8,"") | G8: 9 | H8: 8 | I8: 8 | J8: 6 | K8: =IF(J8="","",1-(J8-1)/9) | L8: 8 | M8: =COUNT(C8,D8,G8,H8,I8,J8,L8)/7 | N8: 3 | O8: =IF(COUNT(C8,D8,G8,H8,I8,J8,L8)=0,"",(IF(MAX($C$5:$C$11)>0,C8/MAX($C$5:$C$11),0)*Assumptions!$B$10+IF(MAX($D$5:$D$11)>0,D8/MAX($D$5:$D$11),0)*Assumptions!$B$11+IF(MAX($E$5:$E$11)>0,E8/MAX($E$5:$E$11),0)*Assumptions!$B$12+IF(G8<>"",G8/10,0)*Assumptions!$B$13+IF(H8<>"",H8/10,0)*Assumptions!$B$14+IF(I8<>"",I8/10,0)*Assumptions!$B$15+IF(K8<>"",K8,0)*Assumptions!$B$16+IF(L8<>"",L8/10,0)*Assumptions!$B$17)*M8) | P8: =IF(O8="","",RANK(O8,$O$5:$O$11,0)+COUNTIF($O$5:O8,O8)-1) | Q8: =IF(O8="","",IF(O8>=Assumptions!$B$22,Assumptions!$A$22,IF(O8>=Assumptions!$B$23,Assumptions!$A$23,IF(O8>=Assumptions!$B$24,Assumptions!$A$24,Assumptions!$A$25)))) | R8: 2030 value is estimated from 2025 market size and reported CAGR; retrofits and IoT integration are strong drivers. | S8: Fragmented standards, project complexity, and long building-investment cycles. | T8: Position around low-current systems, interoperability, and energy-efficiency retrofits. | U8: https://www.grandviewresearch.com/industry-analysis/global-smart-buildings-market
A9: DCA | B9: Data Centre & AI Infrastructure | C9: 356.7 | D9: 1010 | E9: =IF(AND(C9>0,D9>0,Assumptions!$B$7>0),(D9/C9)^(1/Assumptions!$B$7)-1,"") | F9: =IF(AND(C9<>"",D9<>""),D9-C9,"") | G9: 10 | H9: 9 | I9: 7 | J9: 8 | K9: =IF(J9="","",1-(J9-1)/9) | L9: 6 | M9: =COUNT(C9,D9,G9,H9,I9,J9,L9)/7 | N9: 3 | O9: =IF(COUNT(C9,D9,G9,H9,I9,J9,L9)=0,"",(IF(MAX($C$5:$C$11)>0,C9/MAX($C$5:$C$11),0)*Assumptions!$B$10+IF(MAX($D$5:$D$11)>0,D9/MAX($D$5:$D$11),0)*Assumptions!$B$11+IF(MAX($E$5:$E$11)>0,E9/MAX($E$5:$E$11),0)*Assumptions!$B$12+IF(G9<>"",G9/10,0)*Assumptions!$B$13+IF(H9<>"",H9/10,0)*Assumptions!$B$14+IF(I9<>"",I9/10,0)*Assumptions!$B$15+IF(K9<>"",K9,0)*Assumptions!$B$16+IF(L9<>"",L9/10,0)*Assumptions!$B$17)*M9) | P9: =IF(O9="","",RANK(O9,$O$5:$O$11,0)+COUNTIF($O$5:O9,O9)-1) | Q9: =IF(O9="","",IF(O9>=Assumptions!$B$22,Assumptions!$A$22,IF(O9>=Assumptions!$B$23,Assumptions!$A$23,IF(O9>=Assumptions!$B$24,Assumptions!$A$24,Assumptions!$A$25)))) | R9: AI infrastructure is accelerating spending on data-centre equipment, power, cooling, and dense connectivity. | S9: Power availability, capital intensity, and hyperscaler procurement concentration. | T9: Target adjacency plays: optical interconnects, racks/cabling, and regional sourcing support. | U9: https://iot-analytics.com/data-center-infrastructure-market/
A10: ROB | B10: Robotics & Intelligent Devices | C10: 40.8 | D10: 99.1 | E10: =IF(AND(C10>0,D10>0,Assumptions!$B$7>0),(D10/C10)^(1/Assumptions!$B$7)-1,"") | F10: =IF(AND(C10<>"",D10<>""),D10-C10,"") | G10: 9 | H10: 7 | I10: 6 | J10: 7 | K10: =IF(J10="","",1-(J10-1)/9) | L10: 6 | M10: =COUNT(C10,D10,G10,H10,I10,J10,L10)/7 | N10: 3 | O10: =IF(COUNT(C10,D10,G10,H10,I10,J10,L10)=0,"",(IF(MAX($C$5:$C$11)>0,C10/MAX($C$5:$C$11),0)*Assumptions!$B$10+IF(MAX($D$5:$D$11)>0,D10/MAX($D$5:$D$11),0)*Assumptions!$B$11+IF(MAX($E$5:$E$11)>0,E10/MAX($E$5:$E$11),0)*Assumptions!$B$12+IF(G10<>"",G10/10,0)*Assumptions!$B$13+IF(H10<>"",H10/10,0)*Assumptions!$B$14+IF(I10<>"",I10/10,0)*Assumptions!$B$15+IF(K10<>"",K10,0)*Assumptions!$B$16+IF(L10<>"",L10/10,0)*Assumptions!$B$17)*M10) | P10: =IF(O10="","",RANK(O10,$O$5:$O$11,0)+COUNTIF($O$5:O10,O10)-1) | Q10: =IF(O10="","",IF(O10>=Assumptions!$B$22,Assumptions!$A$22,IF(O10>=Assumptions!$B$23,Assumptions!$A$23,IF(O10>=Assumptions!$B$24,Assumptions!$A$24,Assumptions!$A$25)))) | R10: Labor shortages and service automation support rapid growth, especially in logistics and hospitality. | S10: ROI proof, integration complexity, and safety/compliance hurdles slow adoption. | T10: Treat as growth option; build pilot partnerships before scaling inventory commitments. | U10: https://www.knowledge-sourcing.com/report/service-robot-market
A11: CEV | B11: Commercial Electronics & Visual Systems | C11: 57.24 | D11: 78.48 | E11: =IF(AND(C11>0,D11>0,Assumptions!$B$7>0),(D11/C11)^(1/Assumptions!$B$7)-1,"") | F11: =IF(AND(C11<>"",D11<>""),D11-C11,"") | G11: 6 | H11: 7 | I11: 7 | J11: 8 | K11: =IF(J11="","",1-(J11-1)/9) | L11: 7 | M11: =COUNT(C11,D11,G11,H11,I11,J11,L11)/7 | N11: 4 | O11: =IF(COUNT(C11,D11,G11,H11,I11,J11,L11)=0,"",(IF(MAX($C$5:$C$11)>0,C11/MAX($C$5:$C$11),0)*Assumptions!$B$10+IF(MAX($D$5:$D$11)>0,D11/MAX($D$5:$D$11),0)*Assumptions!$B$11+IF(MAX($E$5:$E$11)>0,E11/MAX($E$5:$E$11),0)*Assumptions!$B$12+IF(G11<>"",G11/10,0)*Assumptions!$B$13+IF(H11<>"",H11/10,0)*Assumptions!$B$14+IF(I11<>"",I11/10,0)*Assumptions!$B$15+IF(K11<>"",K11,0)*Assumptions!$B$16+IF(L11<>"",L11/10,0)*Assumptions!$B$17)*M11) | P11: =IF(O11="","",RANK(O11,$O$5:$O$11,0)+COUNTIF($O$5:O11,O11)-1) | Q11: =IF(O11="","",IF(O11>=Assumptions!$B$22,Assumptions!$A$22,IF(O11>=Assumptions!$B$23,Assumptions!$A$23,IF(O11>=Assumptions!$B$24,Assumptions!$A$24,Assumptions!$A$25)))) | R11: Commercial display demand tracks retail modernization, transport upgrades, control rooms, and workplace collaboration. | S11: Project timing, capex sensitivity, and panel price swings. | T11: Compete selectively in project-led segments with integration pull-through rather than pure resale. | U11: https://www.grandviewresearch.com/industry-analysis/commercial-display-market

Sheet Forecast_Model
A1: Annual Forecast Bridge
A4: Industry | B4: =Assumptions!B5 | C4: =B4+1 | D4: =C4+1 | E4: =D4+1 | F4: =Assumptions!B6 | G4: Absolute Growth ($m) | H4: CAGR | I4: Check vs Input Forecast
A5: Telecommunications Infrastructure | B5: =IF(OR(Industry_Data!$C5="",Industry_Data!$E5=""),"",Industry_Data!$C5*(1+Industry_Data!$E5)^(B$4-Assumptions!$B$5)) | C5: =IF(OR(Industry_Data!$C5="",Industry_Data!$E5=""),"",Industry_Data!$C5*(1+Industry_Data!$E5)^(C$4-Assumptions!$B$5)) | D5: =IF(OR(Industry_Data!$C5="",Industry_Data!$E5=""),"",Industry_Data!$C5*(1+Industry_Data!$E5)^(D$4-Assumptions!$B$5)) | E5: =IF(OR(Industry_Data!$C5="",Industry_Data!$E5=""),"",Industry_Data!$C5*(1+Industry_Data!$E5)^(E$4-Assumptions!$B$5)) | F5: =IF(OR(Industry_Data!$C5="",Industry_Data!$E5=""),"",Industry_Data!$C5*(1+Industry_Data!$E5)^(F$4-Assumptions!$B$5)) | G5: =IF(AND(B5<>"",F5<>""),F5-B5,"") | H5: =Industry_Data!E5 | I5: =IF(OR(F5="",Industry_Data!D5=""),"",F5-Industry_Data!D5)
A6: Networking & Data Systems | B6: =IF(OR(Industry_Data!$C6="",Industry_Data!$E6=""),"",Industry_Data!$C6*(1+Industry_Data!$E6)^(B$4-Assumptions!$B$5)) | C6: =IF(OR(Industry_Data!$C6="",Industry_Data!$E6=""),"",Industry_Data!$C6*(1+Industry_Data!$E6)^(C$4-Assumptions!$B$5)) | D6: =IF(OR(Industry_Data!$C6="",Industry_Data!$E6=""),"",Industry_Data!$C6*(1+Industry_Data!$E6)^(D$4-Assumptions!$B$5)) | E6: =IF(OR(Industry_Data!$C6="",Industry_Data!$E6=""),"",Industry_Data!$C6*(1+Industry_Data!$E6)^(E$4-Assumptions!$B$5)) | F6: =IF(OR(Industry_Data!$C6="",Industry_Data!$E6=""),"",Industry_Data!$C6*(1+Industry_Data!$E6)^(F$4-Assumptions!$B$5)) | G6: =IF(AND(B6<>"",F6<>""),F6-B6,"") | H6: =Industry_Data!E6 | I6: =IF(OR(F6="",Industry_Data!D6=""),"",F6-Industry_Data!D6)
A7: Security & Surveillance | B7: =IF(OR(Industry_Data!$C7="",Industry_Data!$E7=""),"",Industry_Data!$C7*(1+Industry_Data!$E7)^(B$4-Assumptions!$B$5)) | C7: =IF(OR(Industry_Data!$C7="",Industry_Data!$E7=""),"",Industry_Data!$C7*(1+Industry_Data!$E7)^(C$4-Assumptions!$B$5)) | D7: =IF(OR(Industry_Data!$C7="",Industry_Data!$E7=""),"",Industry_Data!$C7*(1+Industry_Data!$E7)^(D$4-Assumptions!$B$5)) | E7: =IF(OR(Industry_Data!$C7="",Industry_Data!$E7=""),"",Industry_Data!$C7*(1+Industry_Data!$E7)^(E$4-Assumptions!$B$5)) | F7: =IF(OR(Industry_Data!$C7="",Industry_Data!$E7=""),"",Industry_Data!$C7*(1+Industry_Data!$E7)^(F$4-Assumptions!$B$5)) | G7: =IF(AND(B7<>"",F7<>""),F7-B7,"") | H7: =Industry_Data!E7 | I7: =IF(OR(F7="",Industry_Data!D7=""),"",F7-Industry_Data!D7)
A8: Smart Building & IoT Systems | B8: =IF(OR(Industry_Data!$C8="",Industry_Data!$E8=""),"",Industry_Data!$C8*(1+Industry_Data!$E8)^(B$4-Assumptions!$B$5)) | C8: =IF(OR(Industry_Data!$C8="",Industry_Data!$E8=""),"",Industry_Data!$C8*(1+Industry_Data!$E8)^(C$4-Assumptions!$B$5)) | D8: =IF(OR(Industry_Data!$C8="",Industry_Data!$E8=""),"",Industry_Data!$C8*(1+Industry_Data!$E8)^(D$4-Assumptions!$B$5)) | E8: =IF(OR(Industry_Data!$C8="",Industry_Data!$E8=""),"",Industry_Data!$C8*(1+Industry_Data!$E8)^(E$4-Assumptions!$B$5)) | F8: =IF(OR(Industry_Data!$C8="",Industry_Data!$E8=""),"",Industry_Data!$C8*(1+Industry_Data!$E8)^(F$4-Assumptions!$B$5)) | G8: =IF(AND(B8<>"",F8<>""),F8-B8,"") | H8: =Industry_Data!E8 | I8: =IF(OR(F8="",Industry_Data!D8=""),"",F8-Industry_Data!D8)
A9: Data Centre & AI Infrastructure | B9: =IF(OR(Industry_Data!$C9="",Industry_Data!$E9=""),"",Industry_Data!$C9*(1+Industry_Data!$E9)^(B$4-Assumptions!$B$5)) | C9: =IF(OR(Industry_Data!$C9="",Industry_Data!$E9=""),"",Industry_Data!$C9*(1+Industry_Data!$E9)^(C$4-Assumptions!$B$5)) | D9: =IF(OR(Industry_Data!$C9="",Industry_Data!$E9=""),"",Industry_Data!$C9*(1+Industry_Data!$E9)^(D$4-Assumptions!$B$5)) | E9: =IF(OR(Industry_Data!$C9="",Industry_Data!$E9=""),"",Industry_Data!$C9*(1+Industry_Data!$E9)^(E$4-Assumptions!$B$5)) | F9: =IF(OR(Industry_Data!$C9="",Industry_Data!$E9=""),"",Industry_Data!$C9*(1+Industry_Data!$E9)^(F$4-Assumptions!$B$5)) | G9: =IF(AND(B9<>"",F9<>""),F9-B9,"") | H9: =Industry_Data!E9 | I9: =IF(OR(F9="",Industry_Data!D9=""),"",F9-Industry_Data!D9)
A10: Robotics & Intelligent Devices | B10: =IF(OR(Industry_Data!$C10="",Industry_Data!$E10=""),"",Industry_Data!$C10*(1+Industry_Data!$E10)^(B$4-Assumptions!$B$5)) | C10: =IF(OR(Industry_Data!$C10="",Industry_Data!$E10=""),"",Industry_Data!$C10*(1+Industry_Data!$E10)^(C$4-Assumptions!$B$5)) | D10: =IF(OR(Industry_Data!$C10="",Industry_Data!$E10=""),"",Industry_Data!$C10*(1+Industry_Data!$E10)^(D$4-Assumptions!$B$5)) | E10: =IF(OR(Industry_Data!$C10="",Industry_Data!$E10=""),"",Industry_Data!$C10*(1+Industry_Data!$E10)^(E$4-Assumptions!$B$5)) | F10: =IF(OR(Industry_Data!$C10="",Industry_Data!$E10=""),"",Industry_Data!$C10*(1+Industry_Data!$E10)^(F$4-Assumptions!$B$5)) | G10: =IF(AND(B10<>"",F10<>""),F10-B10,"") | H10: =Industry_Data!E10 | I10: =IF(OR(F10="",Industry_Data!D10=""),"",F10-Industry_Data!D10)
A11: Commercial Electronics & Visual Systems | B11: =IF(OR(Industry_Data!$C11="",Industry_Data!$E11=""),"",Industry_Data!$C11*(1+Industry_Data!$E11)^(B$4-Assumptions!$B$5)) | C11: =IF(OR(Industry_Data!$C11="",Industry_Data!$E11=""),"",Industry_Data!$C11*(1+Industry_Data!$E11)^(C$4-Assumptions!$B$5)) | D11: =IF(OR(Industry_Data!$C11="",Industry_Data!$E11=""),"",Industry_Data!$C11*(1+Industry_Data!$E11)^(D$4-Assumptions!$B$5)) | E11: =IF(OR(Industry_Data!$C11="",Industry_Data!$E11=""),"",Industry_Data!$C11*(1+Industry_Data!$E11)^(E$4-Assumptions!$B$5)) | F11: =IF(OR(Industry_Data!$C11="",Industry_Data!$E11=""),"",Industry_Data!$C11*(1+Industry_Data!$E11)^(F$4-Assumptions!$B$5)) | G11: =IF(AND(B11<>"",F11<>""),F11-B11,"") | H11: =Industry_Data!E11 | I11: =IF(OR(F11="",Industry_Data!D11=""),"",F11-Industry_Data!D11)

Sheet Ranking_Summary
A1: Dominance Ranking Summary
A4: Top Industry | B4: Data Centre & AI Infrastructure | C4: Top Score | D4: 0.872 | E4: Avg Score | F4: 0.532
A6: Rank | B6: Industry | C6: Dominance Score | D6: Current Size ($m) | E6: Forecast Size ($m) | F6: CAGR | G6: Bucket | H6: Main Comment
A7: 1 | B7: Data Centre & AI Infrastructure | C7: 0.872 | D7: 356.7 | E7: 1010 | F7: 0.23141277 | G7: =IF(O9="","",IF(O9>=Assumptions!$B$22,Assumptions!$A$22,IF(O9>=Assumptions!$B$23,Assumptions!$A$23,IF(O9>=Assumptions!$B$24,Assumptions!$A$24,Assumptions!$A$25)))) | H7: AI infrastructure is accelerating spending on data-centre equipment, power, cooling, and dense connectivity.
A8: 2 | B8: Smart Building & IoT Systems | C8: 0.633 | D8: 141.79 | E8: 336.94 | F8: 0.18899874 | G8: =IF(O8="","",IF(O8>=Assumptions!$B$22,Assumptions!$A$22,IF(O8>=Assumptions!$B$23,Assumptions!$A$23,IF(O8>=Assumptions!$B$24,Assumptions!$A$24,Assumptions!$A$25)))) | H8: 2030 value is estimated from 2025 market size and reported CAGR; retrofits and IoT integration are strong drivers.
A9: 3 | B9: Robotics & Intelligent Devices | C9: 0.495 | D9: 40.8 | E9: 99.1 | F9: 0.19421549 | G9: =IF(O10="","",IF(O10>=Assumptions!$B$22,Assumptions!$A$22,IF(O10>=Assumptions!$B$23,Assumptions!$A$23,IF(O10>=Assumptions!$B$24,Assumptions!$A$24,Assumptions!$A$25)))) | H9: Labor shortages and service automation support rapid growth, especially in logistics and hospitality.
A10: 4 | B10: Networking & Data Systems | C10: 0.48 | D10: 124.59 | E10: 193.77 | F10: 0.092347127 | G10: =IF(O6="","",IF(O6>=Assumptions!$B$22,Assumptions!$A$22,IF(O6>=Assumptions!$B$23,Assumptions!$A$23,IF(O6>=Assumptions!$B$24,Assumptions!$A$24,Assumptions!$A$25)))) | H10: Cloud migration, wireless upgrades, and secure enterprise architectures keep demand resilient.
A11: 5 | B11: Security & Surveillance | C11: 0.446 | D11: 120.79 | E11: 151.5 | F11: 0.046348438 | G11: =IF(O7="","",IF(O7>=Assumptions!$B$22,Assumptions!$A$22,IF(O7>=Assumptions!$B$23,Assumptions!$A$23,IF(O7>=Assumptions!$B$24,Assumptions!$A$24,Assumptions!$A$25)))) | H11: Security budgets remain stable and AI analytics expand use cases beyond basic monitoring.
A12: 6 | B12: Telecommunications Infrastructure | C12: 0.431 | D12: 36.69 | E12: 58.65 | F12: 0.098358363 | G12: =IF(O5="","",IF(O5>=Assumptions!$B$22,Assumptions!$A$22,IF(O5>=Assumptions!$B$23,Assumptions!$A$23,IF(O5>=Assumptions!$B$24,Assumptions!$A$24,Assumptions!$A$25)))) | H12: Optics growth is supported by AI interconnect demand, 5G backhaul, and FTTH expansion.
A13: 7 | B13: Commercial Electronics & Visual Systems | C13: 0.365 | D13: 57.24 | E13: 78.48 | F13: 0.065152703 | G13: =IF(O11="","",IF(O11>=Assumptions!$B$22,Assumptions!$A$22,IF(O11>=Assumptions!$B$23,Assumptions!$A$23,IF(O11>=Assumptions!$B$24,Assumptions!$A$24,Assumptions!$A$25)))) | H13: Commercial display demand tracks retail modernization, transport upgrades, control rooms, and workplace collaboration.

Sheet Sources_Log
A1: Source Log
A4: Date Added | B4: Industry | C4: Metric / Topic | D4: Geography | E4: Source Type | F4: Source URL | G4: Publication Date | H4: Key Takeaway | I4: Reliability (1-5)
A5: 2026-03-21 | B5: TEL | C5: Fiber optic components market size / forecast | D5: Global | E5: Market report | F5: https://www.marketsandmarkets.com/PressReleases/fiber-optic-component.asp | G5: 2025-05-02 | H5: 2025 market size USD 36.69bn; 2030 forecast USD 58.65bn; AI + 5G + broadband are key drivers. | I5: 4
A6: 2026-03-21 | B6: NET | C6: Enterprise networking market size / forecast | D6: Global | E6: Market report | F6: https://www.marketsandmarkets.com/PressReleases/enterprise-networking.asp | G6: 2025-04-28 | H6: 2025 market size USD 124.59bn; 2030 forecast USD 193.77bn. | I6: 4
A7: 2026-03-21 | B7: SEC | C7: Physical security market size / forecast | D7: Global | E7: Market report | F7: https://www.marketsandmarkets.com/Market-Reports/physical-security-market-1014.html | G7: 2025 | H7: 2025 market size USD 120.79bn; 2030 forecast USD 151.50bn. | I7: 4
A8: 2026-03-21 | B8: SBL | C8: Smart building market size / CAGR | D8: Global | E8: Market report | F8: https://www.grandviewresearch.com/industry-analysis/global-smart-buildings-market | G8: 2026 | H8: 2025 market size USD 141.79bn; workbook 2030E extrapolated from reported CAGR. | I8: 3
A9: 2026-03-21 | B9: DCA | C9: Data-center equipment & infrastructure market | D9: Global | E9: Market report | F9: https://iot-analytics.com/data-center-infrastructure-market/ | G9: 2025-11-12 | H9: 2024 market size USD 290bn; 2030 forecast USD 1.01tn; workbook 2025E estimated from source growth path. | I9: 4
A10: 2026-03-21 | B10: ROB | C10: Service robotics market size / forecast | D10: Global | E10: Market report | F10: https://www.knowledge-sourcing.com/report/service-robot-market | G10: 2025 | H10: 2025 market size USD 40.8bn; 2030 forecast USD 99.1bn. | I10: 3
A11: 2026-03-21 | B11: CEV | C11: Commercial display market size / forecast | D11: Global | E11: Market report | F11: https://www.grandviewresearch.com/industry-analysis/commercial-display-market | G11: 2026 | H11: 2024 market size USD 53.65bn; 2030 forecast USD 78.48bn; workbook 2025E estimated from CAGR. | I11: 4
A12: 2026-03-21 | B12: ALL | C12: AI power demand and data-center electricity growth | D12: Global | E12: Institutional analysis | F12: https://www.iea.org/reports/energy-and-ai/energy-demand-from-ai | G12: 2025 | H12: Data-centre electricity consumption is projected to roughly double by 2030. | I12: 5
A13: 2026-03-21 | B13: ALL | C13: Mobile traffic / 5G traffic growth | D13: Global | E13: Industry report | F13: https://www.ericsson.com/en/reports-and-papers/mobility-report/dataforecasts/mobile-traffic-forecast | G13: 2026 | H13: 5G share of mobile data traffic rises sharply through 2031, supporting network upgrades. | I13: 4
A14: 2026-03-21 | B14: ALL | C14: Telecom and data-centre geopolitical pressure | D14: Global | E14: Strategy article | F14: https://www.pwc.com/us/en/industries/tmt/library/geo-economic-shifts-in-tech-and-telecom.html | G14: 2025-07-22 | H14: Tariffs, restrictions, and geopolitics are reshaping sourcing strategies. | I14: 4
A15: 2026-03-21 | B15: ROB | C15: Industrial robot deployment trend | D15: Global | E15: Industry federation | F15: https://ifr.org/ifr-press-releases/news/global-robot-demand-in-factories-doubles-over-10-years | G15: 2025-09-25 | H15: Industrial robot installations remained above 500k units in 2024, confirming broad automation demand. | I15: 5
A45: Market regions / countries | B45: World Bank Internet Users indicator | C45: https://data.worldbank.org/indicator/IT.NET.USER.ZS | D45: Country digital adoption baseline / market context
A46: Market regions / countries | B46: ITU Facts and Figures 2025 | C46: https://www.itu.int/en/ITU-D/Statistics/pages/facts/default.aspx | D46: Regional connectivity context and digital development trends
A47: Africa markets | B47: GSMA Mobile Economy Africa 2025 | C47: https://www.gsmaintelligence.com/research/the-mobile-economy-africa-2025 | D47: Mobile and digital economy context for African markets
A48: Global / LATAM / SEA market logic | B48: GSMA Mobile Economy 2025/2026 | C48: https://www.gsma.com/solutions-and-impact/connectivity-for-good/mobile-economy/ | D48: Global mobile and connectivity demand context
A49: Data Centre & AI context | B49: JLL Data Center Outlook 2026 | C49: https://www.jll.com/en-us/insights/market-outlook/data-center-outlook | D49: Data center growth logic used for DCA attractiveness

Sheet TEL_Notes
A1: Telecommunications Infrastructure
A4: Definition | B4: Physical and technological systems that enable the transmission of voice, data, and internet services across local, regional, and global communication networks. | D4: Metric | E4: Linked value
A5: Typical products / systems | B5: fiber optic cables; ODN/closures/cabinets; passive optical components; PON equipment; transmission systems | D5: Current market size ($m) | E5: =Industry_Data!C5
A6: Typical customers | B6: telecom operators; ISPs; infrastructure contractors; system integrators | D6: Forecast market size ($m) | E6: =Industry_Data!D5
A7: Strategic note | B7: Backbone connectivity domain supported by broadband rollout, 5G backhaul, and public network investment. | D7: CAGR | E7: =Industry_Data!E5
D8: Dominance score | E8: =Industry_Data!O5
D9: Rank | E9: =Industry_Data!P5
D10: Bucket | E10: =Industry_Data!Q5
A11: Section | B11: Prompt / Question | C11: Notes / Figures | D11: Source URL | E11: Forecast comment | F11: Confidence | G11: Last update
A12: Market size | B12: What is the current market size? Which geography? | C12: Global market used in workbook: USD 36.69bn (2025/2025E aligned). | D12: https://www.marketsandmarkets.com/PressReleases/fiber-optic-component.asp | E12: Base year aligned to workbook control. | F12: 4 | G12: 2026-03-21
A13: Forecast | B13: What is the forecast size and time horizon? | C13: Workbook forecast: USD 58.65bn by 2030. | D13: https://www.marketsandmarkets.com/PressReleases/fiber-optic-component.asp | E13: Forecast horizon standardized to 2030 for comparison. | F13: 4 | G13: 2026-03-21
A14: Growth | B14: What CAGR or growth logic is reported? | C14: Implied CAGR in workbook: 9.8%. | D14: https://www.marketsandmarkets.com/PressReleases/fiber-optic-component.asp | E14: Useful for cross-industry comparison, not as a precise valuation input. | F14: 4 | G14: 2026-03-21
A15: Competitors | B15: Who are the main global / regional players? | C15: Coherent, Lumentum, Broadcom, Sumitomo, Accelink, Cisco/Acacia, Furukawa. | D15: https://www.marketsandmarkets.com/PressReleases/fiber-optic-component.asp | E15: Competition note reflects broad global landscape. | F15: 3 | G15: 2026-03-21
A16: Demand drivers | B16: Which structural drivers support demand? | C16: FTTH and broadband rollout; 5G backhaul and fronthaul; AI / data-centre interconnect. | D16: https://www.marketsandmarkets.com/PressReleases/fiber-optic-component.asp | E16: Drivers support the qualitative scores in Industry_Data. | F16: 4 | G16: 2026-03-21
A17: Profitability | B17: What is known about margin pool or value capture? | C17: Best value capture usually sits in integration, software, or higher-spec subsystems rather than commodity hardware alone. | D17: https://www.marketsandmarkets.com/PressReleases/fiber-optic-component.asp | E17: Margin pools differ sharply by position in the value chain. | F17: 3 | G17: 2026-03-21
A18: Barriers | B18: What barriers make this industry harder/easier to enter? | C18: Carrier capex delays; Vendor bans / geopolitics; Commodity price pressure. | D18: https://www.marketsandmarkets.com/PressReleases/fiber-optic-component.asp | E18: Entry barriers are a mix of technical, commercial, and regulatory factors. | F18: 3 | G18: 2026-03-21
A20: Demand Driver | B20: Strength (1-10) | C20: Comment | E20: Risk / Constraint | F20: Severity (1-10) | G20: Comment
A21: FTTH and broadband rollout | B21: 9 | C21: Governments and operators continue extending fiber access. | E21: Carrier capex delays | F21: 7 | G21: Telecom spending is cyclical and can pause during macro stress.
A22: 5G backhaul and fronthaul | B22: 8 | C22: Mobile densification increases optical connectivity needs. | E22: Vendor bans / geopolitics | F22: 8 | G22: Restrictions on selected vendors reshape sourcing and standards.
A23: AI / data-centre interconnect | B23: 8 | C23: Higher traffic and lower latency push optical upgrades. | E23: Commodity price pressure | F23: 6 | G23: Basic passive products face margin compression.
A24: Public infrastructure programs | B24: 7 | C24: Subsidized rural and sovereign network projects support demand. | E24: Long qualification cycles | F24: 7 | G24: Carrier approvals slow entry and scale-up.
A29: PESTLE Factor | B29: Impact | C29: Comment | E29: Force | F29: Level | G29: Comment
A30: Political | B30: Medium | C30: Public broadband programs help, but vendor restrictions and trade controls matter. | E30: Rivalry | F30: High | G30: Global and Chinese suppliers compete aggressively on price and lead time.
A31: Economic | B31: Medium | C31: Demand is real but carrier capex and financing cycles affect timing. | E31: Buyer power | F31: High | G31: Large operators and distributors negotiate hard.
A32: Social | B32: Medium | C32: Connectivity remains a baseline service expectation. | E32: Supplier power | F32: Medium | G32: Specialized optical components can tighten supply, but alternatives exist.
A33: Technological | B33: High | C33: 50G-PON, DCI, and AI traffic support upgrades. | E33: New entrants | F33: Medium | G33: Manufacturing is possible, but carrier qualification is hard.
A34: Legal | B34: Medium | C34: Standards, certifications, and data-security rules influence vendors. | E34: Substitutes | F34: Low | G34: Fiber remains the preferred medium for high-capacity fixed access/backbone.
A35: Environmental | B35: Medium | C35: Operators seek lower-power, lower-loss networks. | E35: Overall | F35: Medium | G35: Strategically attractive, but margin capture depends on position in the stack.
C37: Priority rises if broadband rollout and AI-related optical demand reinforce each other in target regions.
A38: Working hypothesis | B38: What would make this industry dominant in your target markets over the next 3-5 years? | C38: Increase priority if target markets show funded FTTH / FTTx projects and stable operator purchasing.
A39: Decision note | B39: What evidence would make you increase or reduce its priority?

Sheet NET_Notes
A1: Networking & Data Systems
A4: Definition | B4: Hardware and software systems that route, distribute, secure, and manage data traffic across enterprise, campus, carrier, and cloud environments. | D4: Metric | E4: Linked value
A5: Typical products / systems | B5: switches; routers; wireless access points; firewalls; structured cabling; network management platforms | D5: Current market size ($m) | E5: =Industry_Data!C6
A6: Typical customers | B6: enterprises; IT integrators; telecom operators; cloud and service providers | D6: Forecast market size ($m) | E6: =Industry_Data!D6
A7: Strategic note | B7: Benefits from enterprise digitalization, cloud migration, and traffic growth, but rivalry is intense. | D7: CAGR | E7: =Industry_Data!E6
D8: Dominance score | E8: =Industry_Data!O6
D9: Rank | E9: =Industry_Data!P6
D10: Bucket | E10: =Industry_Data!Q6
A11: Section | B11: Prompt / Question | C11: Notes / Figures | D11: Source URL | E11: Forecast comment | F11: Confidence | G11: Last update
A12: Market size | B12: What is the current market size? Which geography? | C12: Global market used in workbook: USD 124.59bn (2025/2025E aligned). | D12: https://www.marketsandmarkets.com/PressReleases/enterprise-networking.asp | E12: Base year aligned to workbook control. | F12: 4 | G12: 2026-03-21
A13: Forecast | B13: What is the forecast size and time horizon? | C13: Workbook forecast: USD 193.77bn by 2030. | D13: https://www.marketsandmarkets.com/PressReleases/enterprise-networking.asp | E13: Forecast horizon standardized to 2030 for comparison. | F13: 4 | G13: 2026-03-21
A14: Growth | B14: What CAGR or growth logic is reported? | C14: Implied CAGR in workbook: 9.2%. | D14: https://www.marketsandmarkets.com/PressReleases/enterprise-networking.asp | E14: Useful for cross-industry comparison, not as a precise valuation input. | F14: 4 | G14: 2026-03-21
A15: Competitors | B15: Who are the main global / regional players? | C15: Cisco, HPE Aruba, Juniper, Huawei, H3C, Fortinet, Ubiquiti. | D15: https://www.marketsandmarkets.com/PressReleases/enterprise-networking.asp | E15: Competition note reflects broad global landscape. | F15: 3 | G15: 2026-03-21
A16: Demand drivers | B16: Which structural drivers support demand? | C16: Cloud migration; Wi-Fi / access upgrades; Secure networking. | D16: https://www.marketsandmarkets.com/PressReleases/enterprise-networking.asp | E16: Drivers support the qualitative scores in Industry_Data. | F16: 4 | G16: 2026-03-21
A17: Profitability | B17: What is known about margin pool or value capture? | C17: Best value capture usually sits in integration, software, or higher-spec subsystems rather than commodity hardware alone. | D17: https://www.marketsandmarkets.com/PressReleases/enterprise-networking.asp | E17: Margin pools differ sharply by position in the value chain. | F17: 3 | G17: 2026-03-21
A18: Barriers | B18: What barriers make this industry harder/easier to enter? | C18: High rivalry; Vendor lock-in; Rapid refresh cycles. | D18: https://www.marketsandmarkets.com/PressReleases/enterprise-networking.asp | E18: Entry barriers are a mix of technical, commercial, and regulatory factors. | F18: 3 | G18: 2026-03-21
A20: Demand Driver | B20: Strength (1-10) | C20: Comment | E20: Risk / Constraint | F20: Severity (1-10) | G20: Comment
A21: Cloud migration | B21: 8 | C21: More hybrid architectures require refresh of campus and edge networks. | E21: High rivalry | F21: 8 | G21: Strong brands and channel saturation compress margins.
A22: Wi-Fi / access upgrades | B22: 8 | C22: Higher traffic and device density drive AP and switch demand. | E22: Vendor lock-in | F22: 7 | G22: Installed-base ecosystems make share capture harder.
A23: Secure networking | B23: 8 | C23: SASE, SD-WAN, and segmentation raise value per deployment. | E23: Rapid refresh cycles | F23: 6 | G23: Inventory risk rises when standards change quickly.
A24: Data traffic growth | B24: 7 | C24: Enterprise applications and video workloads keep networks expanding. | E24: Price competition | F24: 7 | G24: Hardware-only offers are vulnerable to discounting.
A29: PESTLE Factor | B29: Impact | C29: Comment | E29: Force | F29: Level | G29: Comment
A30: Political | B30: Medium | C30: Procurement preferences and country restrictions matter in some tenders. | E30: Rivalry | F30: High | G30: Global incumbents dominate share and ecosystem relationships.
A31: Economic | B31: Medium | C31: Enterprise IT budgets slow in downturns but networking stays mission-critical. | E31: Buyer power | F31: High | G31: Large enterprise and carrier buyers have many alternatives.
A32: Social | B32: Medium | C32: Always-on connectivity is expected across work and services. | E32: Supplier power | F32: Medium | G32: Chipset dependencies matter, but multi-vendor sourcing is possible.
A33: Technological | B33: High | C33: Cloud, Wi-Fi 7, SDN, and AI operations accelerate refresh. | E33: New entrants | F33: Medium | G33: Software-led entrants can win niches, but broad scale is hard.
A34: Legal | B34: Medium | C34: Cybersecurity and compliance rules shape architecture choices. | E34: Substitutes | F34: Medium | G34: Managed services and cloud networking can replace some on-prem demand.
A35: Environmental | B35: Low | C35: Efficiency matters, but it is not the main buying trigger. | E35: Overall | F35: Medium | G35: Useful adjacency, but differentiation must go beyond pure product resale.
C37: Priority rises if PlanetFiber can bundle networking with security, datacenter, or smart-building projects.
A38: Working hypothesis | B38: What would make this industry dominant in your target markets over the next 3-5 years? | C38: Raise priority if recurring services, integration pull-through, or exclusive vendor rights improve margins.
A39: Decision note | B39: What evidence would make you increase or reduce its priority?

Sheet SEC_Notes
A1: Security & Surveillance
A4: Definition | B4: Technologies used to monitor, control, and protect physical environments, assets, and people through integrated security and surveillance systems. | D4: Metric | E4: Linked value
A5: Typical products / systems | B5: CCTV cameras; VMS; NVR/DVR; access control; alarms; perimeter systems | D5: Current market size ($m) | E5: =Industry_Data!C7
A6: Typical customers | B6: security integrators; facility operators; government contractors; infrastructure developers | D6: Forecast market size ($m) | E6: =Industry_Data!D7
A7: Strategic note | B7: Demand is shaped by safety budgets, regulation, and rising use of AI-enabled monitoring. | D7: CAGR | E7: =Industry_Data!E7
D8: Dominance score | E8: =Industry_Data!O7
D9: Rank | E9: =Industry_Data!P7
D10: Bucket | E10: =Industry_Data!Q7
A11: Section | B11: Prompt / Question | C11: Notes / Figures | D11: Source URL | E11: Forecast comment | F11: Confidence | G11: Last update
A12: Market size | B12: What is the current market size? Which geography? | C12: Global market used in workbook: USD 120.79bn (2025/2025E aligned). | D12: https://www.marketsandmarkets.com/Market-Reports/physical-security-market-1014.html | E12: Base year aligned to workbook control. | F12: 4 | G12: 2026-03-21
A13: Forecast | B13: What is the forecast size and time horizon? | C13: Workbook forecast: USD 151.50bn by 2030. | D13: https://www.marketsandmarkets.com/Market-Reports/physical-security-market-1014.html | E13: Forecast horizon standardized to 2030 for comparison. | F13: 4 | G13: 2026-03-21
A14: Growth | B14: What CAGR or growth logic is reported? | C14: Implied CAGR in workbook: 4.6%. | D14: https://www.marketsandmarkets.com/Market-Reports/physical-security-market-1014.html | E14: Useful for cross-industry comparison, not as a precise valuation input. | F14: 4 | G14: 2026-03-21
A15: Competitors | B15: Who are the main global / regional players? | C15: Hikvision, Dahua, Axis, Hanwha Vision, Bosch, Honeywell, Motorola Solutions. | D15: https://www.marketsandmarkets.com/Market-Reports/physical-security-market-1014.html | E15: Competition note reflects broad global landscape. | F15: 3 | G15: 2026-03-21
A16: Demand drivers | B16: Which structural drivers support demand? | C16: Critical-infrastructure protection; AI analytics; Urbanization and real-estate projects. | D16: https://www.marketsandmarkets.com/Market-Reports/physical-security-market-1014.html | E16: Drivers support the qualitative scores in Industry_Data. | F16: 4 | G16: 2026-03-21
A17: Profitability | B17: What is known about margin pool or value capture? | C17: Best value capture usually sits in integration, software, or higher-spec subsystems rather than commodity hardware alone. | D17: https://www.marketsandmarkets.com/Market-Reports/physical-security-market-1014.html | E17: Margin pools differ sharply by position in the value chain. | F17: 3 | G17: 2026-03-21
A18: Barriers | B18: What barriers make this industry harder/easier to enter? | C18: Privacy and cyber rules; Hardware commoditization; Geopolitical vendor scrutiny. | D18: https://www.marketsandmarkets.com/Market-Reports/physical-security-market-1014.html | E18: Entry barriers are a mix of technical, commercial, and regulatory factors. | F18: 3 | G18: 2026-03-21
A20: Demand Driver | B20: Strength (1-10) | C20: Comment | E20: Risk / Constraint | F20: Severity (1-10) | G20: Comment
A21: Critical-infrastructure protection | B21: 8 | C21: Governments and enterprises continue raising protection budgets. | E21: Privacy and cyber rules | F21: 8 | G21: Compliance requirements increase solution complexity.
A22: AI analytics | B22: 8 | C22: Video shifts from recording to operational intelligence. | E22: Hardware commoditization | F22: 7 | G22: Camera hardware faces intense price pressure.
A23: Urbanization and real-estate projects | B23: 7 | C23: New facilities require integrated monitoring and access. | E23: Geopolitical vendor scrutiny | F23: 7 | G23: Public tenders may exclude selected brands.
A24: Insurance / compliance requirements | B24: 7 | C24: Risk management sustains baseline demand. | E24: Project quality risk | F24: 6 | G24: Poor installation harms performance and reputation.
A29: PESTLE Factor | B29: Impact | C29: Comment | E29: Force | F29: Level | G29: Comment
A30: Political | B30: Medium | C30: Public security spending helps, but vendor approvals vary by market. | E30: Rivalry | F30: High | G30: Many hardware vendors compete globally and regionally.
A31: Economic | B31: Medium | C31: Security budgets are relatively resilient compared with discretionary capex. | E31: Buyer power | F31: Medium | G31: Integrators and end users can switch, but project complexity reduces comparability.
A32: Social | B32: High | C32: Safety concerns support persistent demand. | E32: Supplier power | F32: Medium | G32: Key components matter, but the vendor base is broad.
A33: Technological | B33: High | C33: AI analytics, cloud VMS, and edge processing expand value. | E33: New entrants | F33: Medium | G33: Assembly entry is feasible; trusted brands and channels are harder to build.
A34: Legal | B34: High | C34: Privacy, retention, and cyber rules are central to product selection. | E34: Substitutes | F34: Low | G34: Security functions remain required even if technology mix changes.
A35: Environmental | B35: Low | C35: Power efficiency matters but is secondary. | E35: Overall | F35: Medium | G35: Good fit when bundled with integration and compliance know-how.
C37: Priority rises if security is sold as an integrated systems stack, not just camera hardware.
A38: Working hypothesis | B38: What would make this industry dominant in your target markets over the next 3-5 years? | C38: Increase priority if your channels can win regulated verticals and service-heavy projects.
A39: Decision note | B39: What evidence would make you increase or reduce its priority?

Sheet SBL_Notes
A1: Smart Building & IoT Systems
A4: Definition | B4: Connected building systems that integrate sensors, controllers, software, and devices to optimize building operations, energy use, communications, and user experience. | D4: Metric | E4: Linked value
A5: Typical products / systems | B5: BMS; intercom; access control; IoT sensors; automation controllers; smart office and smart home devices | D5: Current market size ($m) | E5: =Industry_Data!C8
A6: Typical customers | B6: developers; EPCs; smart-building integrators; facility managers; real estate owners | D6: Forecast market size ($m) | E6: =Industry_Data!D8
A7: Strategic note | B7: High-growth domain tied to efficiency retrofits, premium real estate, and smart-city investment. | D7: CAGR | E7: =Industry_Data!E8
D8: Dominance score | E8: =Industry_Data!O8
D9: Rank | E9: =Industry_Data!P8
D10: Bucket | E10: =Industry_Data!Q8
A11: Section | B11: Prompt / Question | C11: Notes / Figures | D11: Source URL | E11: Forecast comment | F11: Confidence | G11: Last update
A12: Market size | B12: What is the current market size? Which geography? | C12: Global market used in workbook: USD 141.79bn (2025/2025E aligned). | D12: https://www.grandviewresearch.com/industry-analysis/global-smart-buildings-market | E12: Base year aligned to workbook control. | F12: 3 | G12: 2026-03-21
A13: Forecast | B13: What is the forecast size and time horizon? | C13: Workbook forecast: USD 336.94bn by 2030. | D13: https://www.grandviewresearch.com/industry-analysis/global-smart-buildings-market | E13: Forecast horizon standardized to 2030 for comparison. | F13: 3 | G13: 2026-03-21
A14: Growth | B14: What CAGR or growth logic is reported? | C14: Implied CAGR in workbook: 18.9%. | D14: https://www.grandviewresearch.com/industry-analysis/global-smart-buildings-market | E14: Useful for cross-industry comparison, not as a precise valuation input. | F14: 3 | G14: 2026-03-21
A15: Competitors | B15: Who are the main global / regional players? | C15: Schneider Electric, Siemens, Honeywell, Johnson Controls, ABB, Legrand. | D15: https://www.grandviewresearch.com/industry-analysis/global-smart-buildings-market | E15: Competition note reflects broad global landscape. | F15: 3 | G15: 2026-03-21
A16: Demand drivers | B16: Which structural drivers support demand? | C16: Energy-efficiency retrofits; IoT/BMS integration; Smart-city and premium real estate. | D16: https://www.grandviewresearch.com/industry-analysis/global-smart-buildings-market | E16: Drivers support the qualitative scores in Industry_Data. | F16: 3 | G16: 2026-03-21
A17: Profitability | B17: What is known about margin pool or value capture? | C17: Best value capture usually sits in integration, software, or higher-spec subsystems rather than commodity hardware alone. | D17: https://www.grandviewresearch.com/industry-analysis/global-smart-buildings-market | E17: Margin pools differ sharply by position in the value chain. | F17: 3 | G17: 2026-03-21
A18: Barriers | B18: What barriers make this industry harder/easier to enter? | C18: Interoperability issues; Long project cycles; Retrofit complexity. | D18: https://www.grandviewresearch.com/industry-analysis/global-smart-buildings-market | E18: Entry barriers are a mix of technical, commercial, and regulatory factors. | F18: 3 | G18: 2026-03-21
A20: Demand Driver | B20: Strength (1-10) | C20: Comment | E20: Risk / Constraint | F20: Severity (1-10) | G20: Comment
A21: Energy-efficiency retrofits | B21: 9 | C21: Owners are upgrading controls to reduce operating cost. | E21: Interoperability issues | F21: 7 | G21: Mixed standards increase engineering complexity.
A22: IoT/BMS integration | B22: 8 | C22: Buildings increasingly act as managed digital assets. | E22: Long project cycles | F22: 7 | G22: Construction timing creates long cash-conversion periods.
A23: Smart-city and premium real estate | B23: 8 | C23: New developments specify integrated low-current systems. | E23: Retrofit complexity | F23: 6 | G23: Legacy buildings can be costly to upgrade.
A24: Hospitality / office modernization | B24: 7 | C24: Guest and user experience drives automation demand. | E24: Fragmented procurement | F24: 6 | G24: Decisions may be split across developers, EPCs, and operators.
A29: PESTLE Factor | B29: Impact | C29: Comment | E29: Force | F29: Level | G29: Comment
A30: Political | B30: Medium | C30: Smart-city and building-efficiency policies support demand. | E30: Rivalry | F30: Medium | G30: Many vendors exist, but systems integration reduces pure price comparability.
A31: Economic | B31: Medium | C31: Construction cycles affect timing, but retrofit ROI can sustain projects. | E31: Buyer power | F31: Medium | G31: Owners and developers are powerful but often rely on trusted integrators.
A32: Social | B32: Medium | C32: Users increasingly expect safer, greener, smarter environments. | E32: Supplier power | F32: Medium | G32: No single hardware category dominates the entire solution.
A33: Technological | B33: High | C33: IoT, analytics, and control platforms are core value drivers. | E33: New entrants | F33: Medium | G33: Entry is possible, but interoperability and project delivery matter.
A34: Legal | B34: High | C34: Energy codes, safety rules, and access-control requirements help adoption. | E34: Substitutes | F34: Medium | G34: Basic non-smart systems remain cheaper in low-end projects.
A35: Environmental | B35: High | C35: Efficiency and emissions pressure strongly support smart building investments. | E35: Overall | F35: High | G35: Strong strategic adjacency to security, AV, and low-current integration.
C37: Priority rises if the ecosystem can combine devices, sourcing, and integration for retrofit projects.
A38: Working hypothesis | B38: What would make this industry dominant in your target markets over the next 3-5 years? | C38: Raise priority if target countries show strong energy rules, real-estate activity, and smart-city spending.
A39: Decision note | B39: What evidence would make you increase or reduce its priority?

Sheet DCA_Notes
A1: Data Centre & AI Infrastructure
A4: Definition | B4: High-performance infrastructure used to support cloud, storage, compute, and AI workloads, including dense connectivity, power, and cooling systems. | D4: Metric | E4: Linked value
A5: Typical products / systems | B5: high-speed optical interconnects; racks; structured connectivity; power distribution; cooling systems | D5: Current market size ($m) | E5: =Industry_Data!C9
A6: Typical customers | B6: hyperscalers; colocation operators; cloud providers; AI infrastructure companies; governments | D6: Forecast market size ($m) | E6: =Industry_Data!D9
A7: Strategic note | B7: Fastest strategic growth cluster, but constrained by power, capital intensity, and technical complexity. | D7: CAGR | E7: =Industry_Data!E9
D8: Dominance score | E8: =Industry_Data!O9
D9: Rank | E9: =Industry_Data!P9
D10: Bucket | E10: =Industry_Data!Q9
A11: Section | B11: Prompt / Question | C11: Notes / Figures | D11: Source URL | E11: Forecast comment | F11: Confidence | G11: Last update
A12: Market size | B12: What is the current market size? Which geography? | C12: Global market used in workbook: USD 356.70bn (2025/2025E aligned). | D12: https://iot-analytics.com/data-center-infrastructure-market/ | E12: Base year aligned to workbook control. | F12: 3 | G12: 2026-03-21
A13: Forecast | B13: What is the forecast size and time horizon? | C13: Workbook forecast: USD 1010.00bn by 2030. | D13: https://iot-analytics.com/data-center-infrastructure-market/ | E13: Forecast horizon standardized to 2030 for comparison. | F13: 3 | G13: 2026-03-21
A14: Growth | B14: What CAGR or growth logic is reported? | C14: Implied CAGR in workbook: 23.1%. | D14: https://iot-analytics.com/data-center-infrastructure-market/ | E14: Useful for cross-industry comparison, not as a precise valuation input. | F14: 3 | G14: 2026-03-21
A15: Competitors | B15: Who are the main global / regional players? | C15: Schneider Electric, Vertiv, Eaton, Dell, HPE, Huawei Digital Power, Supermicro. | D15: https://iot-analytics.com/data-center-infrastructure-market/ | E15: Competition note reflects broad global landscape. | F15: 3 | G15: 2026-03-21
A16: Demand drivers | B16: Which structural drivers support demand? | C16: AI model training and inference; Hyperscaler and colocation capex; Sovereign data / localization. | D16: https://iot-analytics.com/data-center-infrastructure-market/ | E16: Drivers support the qualitative scores in Industry_Data. | F16: 3 | G16: 2026-03-21
A17: Profitability | B17: What is known about margin pool or value capture? | C17: Best value capture usually sits in integration, software, or higher-spec subsystems rather than commodity hardware alone. | D17: https://iot-analytics.com/data-center-infrastructure-market/ | E17: Margin pools differ sharply by position in the value chain. | F17: 3 | G17: 2026-03-21
A18: Barriers | B18: What barriers make this industry harder/easier to enter? | C18: Power availability; Capital intensity; Procurement concentration. | D18: https://iot-analytics.com/data-center-infrastructure-market/ | E18: Entry barriers are a mix of technical, commercial, and regulatory factors. | F18: 3 | G18: 2026-03-21
A20: Demand Driver | B20: Strength (1-10) | C20: Comment | E20: Risk / Constraint | F20: Severity (1-10) | G20: Comment
A21: AI model training and inference | B21: 10 | C21: GPU clusters drive rapid expansion in dense infrastructure. | E21: Power availability | F21: 10 | G21: Grid constraints can delay projects.
A22: Hyperscaler and colocation capex | B22: 9 | C22: Large operators are scaling new capacity aggressively. | E22: Capital intensity | F22: 9 | G22: Large budgets and long lead times raise execution risk.
A23: Sovereign data / localization | B23: 7 | C23: Governments want more local compute and storage. | E23: Procurement concentration | F23: 8 | G23: Hyperscalers and a few major buyers dominate.
